<?xml version="1.0"?>
<sdf version='1.6'>
  <model name='airmedic'>
    <link name='base_link'>
      <inertial>
        <pose>0 0 0 0 0 0</pose>
        <mass>28.103</mass>
        <inertia>
          <ixx>4.83869</ixx>
          <ixy>8.9699e-05</ixy>
          <ixz>0.000374192</ixz>
          <iyy>10.1119</iyy>
          <iyz>0.0988308</iyz>
          <izz>13.8095</izz>
        </inertia>
      </inertial>
      <collision name='base_link_collision'>
        <pose>0 0 0 0 -0 0</pose>
        <geometry>
          <mesh>
            <scale>1 1 1</scale>
            <uri>model://airmedic/meshes/base_link.dae</uri>
          </mesh>
        </geometry>
      </collision>
      <visual name='base_link_visual'>
        <pose>0 0 0 0 -0 0</pose>
        <geometry>
          <mesh>
            <scale>1 1 1</scale>
            <uri>model://airmedic/meshes/base_link.dae</uri>
          </mesh>
        </geometry>
        <material>
          <script>
            <name>Gazebo/DarkGrey</name>
            <uri>__default__</uri>
          </script>
        </material>
      </visual>
    </link>
    <link name='airmedic/imu_link'>
      <pose>0 0 0 0 0 0</pose>
      <inertial>
        <pose>0 0 0 0 0 0</pose>
        <mass>0.015</mass>
        <inertia>
          <ixx>1e-05</ixx>
          <ixy>0</ixy>
          <ixz>0</ixz>
          <iyy>1e-05</iyy>
          <iyz>0</iyz>
          <izz>1e-05</izz>
        </inertia>
      </inertial>
    </link>
    <joint name='airmedic/imu_joint' type='revolute'>
      <child>airmedic/imu_link</child>
      <parent>base_link</parent>
      <axis>
        <xyz>1 0 0</xyz>
        <limit>
          <lower>0</lower>
          <upper>0</upper>
          <effort>0</effort>
          <velocity>0</velocity>
        </limit>
        <dynamics>
          <spring_reference>0</spring_reference>
          <spring_stiffness>0</spring_stiffness>
        </dynamics>
        <use_parent_model_frame>1</use_parent_model_frame>
      </axis>
    </joint>
    <include>
      <uri>model://airspeed</uri>
      <pose>0 0 0 0 0 0</pose>
      <name>airspeed</name>
    </include>
    <include>
      <uri>model://gps</uri>
      <pose>0 0 0 0 0 0</pose>
      <name>gps</name>
    </include>
    <joint name='ZAK_lev' type='revolute'>
      <pose relative_to='base_link'>-0.23314 -0.23212 0.12214 0 -0 0</pose>
      <parent>base_link</parent>
      <child>Link_1</child>
      <axis>
        <xyz>1 0 0</xyz>
        <limit>
          <lower>0</lower>
          <upper>0.5236</upper>
          <effort>0</effort>
          <velocity>0</velocity>
        </limit>
        <dynamics>
          <spring_reference>0</spring_reference>
          <spring_stiffness>0</spring_stiffness>
        </dynamics>
      </axis>
    </joint>
    <link name='Link_1'>
      <pose relative_to='ZAK_lev'>0 0 0 0 -0 0</pose>
      <inertial>
        <pose>-0.35639 -0.029011 -0.003831 0 -0 0</pose>
        <mass>0.2</mass>
        <inertia>
          <ixx>0.015944</ixx>
          <ixy>-1.4384e-07</ixy>
          <ixz>-9.8916e-08</ixz>
          <iyy>0.65898</iyy>
          <iyz>-0.0017589</iyz>
          <izz>0.67239</izz>
        </inertia>
      </inertial>
      <collision name='Link_1_collision'>
        <pose>0 0 0 0 -0 0</pose>
        <geometry>
          <mesh>
            <scale>1 1 1</scale>
            <uri>model://airmedic/meshes/Link_1.dae</uri>
          </mesh>
        </geometry>
      </collision>
      <visual name='Link_1_visual'>
        <pose>0 0 0 0 -0 0</pose>
        <geometry>
          <mesh>
            <scale>1 1 1</scale>
            <uri>model://airmedic/meshes/Link_1.dae</uri>
          </mesh>
        </geometry>
        <material>
          <script>
            <name>Gazebo/Green</name>
            <uri>__default__</uri>
          </script>
        </material>
      </visual>
    </link>
    <joint name='ZAK_prav' type='revolute'>
      <pose relative_to='base_link'>0.23314 -0.23212 0.12214 0 -0 0</pose>
      <parent>base_link</parent>
      <child>Link_2</child>
      <axis>
        <xyz>1 0 0</xyz>
        <limit>
          <lower>0</lower>
          <upper>0.5236</upper>
          <effort>0</effort>
          <velocity>0</velocity>
        </limit>
        <dynamics>
          <spring_reference>0</spring_reference>
          <spring_stiffness>0</spring_stiffness>
        </dynamics>
      </axis>
    </joint>
    <link name='Link_2'>
      <pose relative_to='ZAK_prav'>0 0 0 0 -0 0</pose>
      <inertial>
        <pose>0.35639 -0.029011 -0.003831 0 -0 0</pose>
        <mass>0.2</mass>
        <inertia>
          <ixx>0.015944</ixx>
          <ixy>1.4426e-07</ixy>
          <ixz>9.9047e-08</ixz>
          <iyy>0.65898</iyy>
          <iyz>-0.0017589</iyz>
          <izz>0.67239</izz>
        </inertia>
      </inertial>
      <collision name='Link_2_collision'>
        <pose>0 0 0 0 -0 0</pose>
        <geometry>
          <mesh>
            <scale>1 1 1</scale>
            <uri>model://airmedic/meshes/Link_2.dae</uri>
          </mesh>
        </geometry>
      </collision>
      <visual name='Link_2_visual'>
        <pose>0 0 0 0 -0 0</pose>
        <geometry>
          <mesh>
            <scale>1 1 1</scale>
            <uri>model://airmedic/meshes/Link_2.dae</uri>
          </mesh>
        </geometry>
        <material>
          <script>
            <name>Gazebo/Green</name>
            <uri>__default__</uri>
          </script>
        </material>
      </visual>
    </link>
    <joint name='EL_lev' type='revolute'>
      <pose relative_to='base_link'>-0.936929 -0.232124 0.122136 0 -0 0</pose>
      <parent>base_link</parent>
      <child>Link_3</child>
      <axis>
        <xyz>1 0 0</xyz>
        <limit>
          <lower>-0.43633</lower>
          <upper>0.43633</upper>
          <effort>0</effort>
          <velocity>0</velocity>
        </limit>
        <dynamics>
          <spring_reference>0</spring_reference>
          <spring_stiffness>0</spring_stiffness>
        </dynamics>
      </axis>
    </joint>
    <link name='Link_3'>
      <pose relative_to='EL_lev'>0 0 0 0 -0 0</pose>
      <inertial>
        <pose>-0.40211 -0.029 -0.00383 0 -0 0</pose>
        <mass>0.2</mass>
        <inertia>
          <ixx>0.017547</ixx>
          <ixy>-1.8362e-11</ixy>
          <ixz>5.6041e-11</ixz>
          <iyy>0.8783</iyy>
          <iyz>-0.0019359</iyz>
          <izz>0.89306</izz>
        </inertia>
      </inertial>
      <collision name='Link_3_collision'>
        <pose>0 0 0 0 -0 0</pose>
        <geometry>
          <mesh>
            <scale>1 1 1</scale>
            <uri>model://airmedic/meshes/Link_3.dae</uri>
          </mesh>
        </geometry>
      </collision>
      <visual name='Link_3_visual'>
        <pose>0 0 0 0 -0 0</pose>
        <geometry>
          <mesh>
            <scale>1 1 1</scale>
            <uri>model://airmedic/meshes/Link_3.dae</uri>
          </mesh>
        </geometry>
        <material>
          <script>
            <name>Gazebo/Blue</name>
            <uri>__default__</uri>
          </script>
        </material>
      </visual>
    </link>
    <joint name='EL_prav' type='revolute'>
      <pose relative_to='base_link'>0.936929 -0.232124 0.122136 0 -0 0</pose>
      <parent>base_link</parent>
      <child>Link_4</child>
      <axis>
        <xyz>1 0 0</xyz>
        <limit>
          <lower>-0.43633</lower>
          <upper>0.43633</upper>
          <effort>0</effort>
          <velocity>0</velocity>
        </limit>
        <dynamics>
          <spring_reference>0</spring_reference>
          <spring_stiffness>0</spring_stiffness>
        </dynamics>
      </axis>
    </joint>
    <link name='Link_4'>
      <pose relative_to='EL_prav'>0 0 0 0 -0 0</pose>
      <inertial>
        <pose>0.40211 -0.029 -0.00383 0 -0 0</pose>
        <mass>0.2</mass>
        <inertia>
          <ixx>0.017547</ixx>
          <ixy>-1.2864e-11</ixy>
          <ixz>4.4513e-11</ixz>
          <iyy>0.8783</iyy>
          <iyz>-0.0019359</iyz>
          <izz>0.89306</izz>
        </inertia>
      </inertial>
      <collision name='Link_4_collision'>
        <pose>0 0 0 0 -0 0</pose>
        <geometry>
          <mesh>
            <scale>1 1 1</scale>
            <uri>model://airmedic/meshes/Link_4.dae</uri>
          </mesh>
        </geometry>
      </collision>
      <visual name='Link_4_visual'>
        <pose>0 0 0 0 -0 0</pose>
        <geometry>
          <mesh>
            <scale>1 1 1</scale>
            <uri>model://airmedic/meshes/Link_4.dae</uri>
          </mesh>
        </geometry>
        <material>
          <script>
            <name>Gazebo/Blue</name>
            <uri>__default__</uri>
          </script>
        </material>
      </visual>
    </link>
    <joint name='RN' type='revolute'>
      <pose relative_to='base_link'>0 -1.58357 0.280943 0 -0 0</pose>
      <parent>base_link</parent>
      <child>Link_7</child>
      <axis>
        <xyz>0 0.659668 -0.751557</xyz>
        <limit>
          <lower>-0.34907</lower>
          <upper>0.34907</upper>
          <effort>0</effort>
          <velocity>0</velocity>
        </limit>
        <dynamics>
          <spring_reference>0</spring_reference>
          <spring_stiffness>0</spring_stiffness>
        </dynamics>
      </axis>
    </joint>
    <link name='Link_7'>
      <pose relative_to='RN'>0 0 0 0 -0 0</pose>
      <inertial>
        <pose>0 -0.026924 -0.041927 0 -0 0</pose>
        <mass>0.18</mass>
        <inertia>
          <ixx>0.13173</ixx>
          <ixy>3.7072e-08</ixy>
          <ixz>-6.3187e-08</ixz>
          <iyy>0.069357</iyy>
          <iyz>0.05078</iyz>
          <izz>0.063353</izz>
        </inertia>
      </inertial>
      <collision name='Link_7_collision'>
        <pose>0 0 0 0 -0 0</pose>
        <geometry>
          <mesh>
            <scale>1 1 1</scale>
            <uri>model://airmedic/meshes/Link_7.dae</uri>
          </mesh>
        </geometry>
      </collision>
      <visual name='Link_7_visual'>
        <pose>0 0 0 0 -0 0</pose>
        <geometry>
          <mesh>
            <scale>1 1 1</scale>
            <uri>model://airmedic/meshes/Link_7.dae</uri>
          </mesh>
        </geometry>
        <material>
          <script>
            <name>Gazebo/Blue</name>
            <uri>__default__</uri>
          </script>
        </material>
      </visual>
    </link>
    <joint name='RV_lev' type='revolute'>
      <pose relative_to='base_link'>-0.0545 -1.49297 0.036984 0 -0 0</pose>
      <parent>base_link</parent>
      <child>Link_5</child>
      <axis>
        <xyz>1 0 0</xyz>
        <limit>
          <lower>-0.43633</lower>
          <upper>0.43633</upper>
          <effort>0</effort>
          <velocity>0</velocity>
        </limit>
        <dynamics>
          <spring_reference>0</spring_reference>
          <spring_stiffness>0</spring_stiffness>
        </dynamics>
      </axis>
    </joint>
    <link name='Link_5'>
      <pose relative_to='RV_lev'>0 0 0 0 -0 0</pose>
      <inertial>
        <pose>-0.23931 -0.042661 0.000745 0 -0 0</pose>
        <mass>0.16</mass>
        <inertia>
          <ixx>0.0094971</ixx>
          <ixy>-1.5388e-05</ixy>
          <ixz>2.8568e-07</ixz>
          <iyy>0.13067</iyy>
          <iyz>0.00015862</iyz>
          <izz>0.13975</izz>
        </inertia>
      </inertial>
      <collision name='Link_5_collision'>
        <pose>0 0 0 0 -0 0</pose>
        <geometry>
          <mesh>
            <scale>1 1 1</scale>
            <uri>model://airmedic/meshes/Link_5.dae</uri>
          </mesh>
        </geometry>
      </collision>
      <visual name='Link_5_visual'>
        <pose>0 0 0 0 -0 0</pose>
        <geometry>
          <mesh>
            <scale>1 1 1</scale>
            <uri>model://airmedic/meshes/Link_5.dae</uri>
          </mesh>
        </geometry>
        <material>
          <script>
            <name>Gazebo/Blue</name>
            <uri>__default__</uri>
          </script>
        </material>
      </visual>
    </link>
    <joint name='RV_prav' type='revolute'>
      <pose relative_to='base_link'>0.0545 -1.49297 0.036984 0 -0 0</pose>
      <parent>base_link</parent>
      <child>Link_6</child>
      <axis>
        <xyz>1 0 0</xyz>
        <limit>
          <lower>-0.43633</lower>
          <upper>0.43633</upper>
          <effort>0</effort>
          <velocity>0</velocity>
        </limit>
        <dynamics>
          <spring_reference>0</spring_reference>
          <spring_stiffness>0</spring_stiffness>
        </dynamics>
      </axis>
    </joint>
    <link name='Link_6'>
      <pose relative_to='RV_prav'>0 0 0 0 -0 0</pose>
      <inertial>
        <pose>0.23931 -0.042662 0.000745 0 -0 0</pose>
        <mass>0.16</mass>
        <inertia>
          <ixx>0.0094976</ixx>
          <ixy>1.4914e-05</ixy>
          <ixz>-3.1051e-07</ixz>
          <iyy>0.13067</iyy>
          <iyz>0.00015857</iyz>
          <izz>0.13975</izz>
        </inertia>
      </inertial>
      <collision name='Link_6_collision'>
        <pose>0 0 0 0 -0 0</pose>
        <geometry>
          <mesh>
            <scale>1 1 1</scale>
            <uri>model://airmedic/meshes/Link_6.dae</uri>
          </mesh>
        </geometry>
      </collision>
      <visual name='Link_6_visual'>
        <pose>0 0 0 0 -0 0</pose>
        <geometry>
          <mesh>
            <scale>1 1 1</scale>
            <uri>model://airmedic/meshes/Link_6.dae</uri>
          </mesh>
        </geometry>
        <material>
          <script>
            <name>Gazebo/Blue</name>
            <uri>__default__</uri>
          </script>
        </material>
      </visual>
    </link>
    <joint name='VV1' type='revolute'>
      <pose relative_to='base_link'>0.642857 0.643017 0.221242 0 -0 0</pose>
      <parent>base_link</parent>
      <child>Link_8</child>
      <axis>
        <xyz>0 0 1</xyz>
        <limit>
          <lower>-1e+16</lower>
          <upper>1e+16</upper>
        </limit>
        <dynamics>
          <spring_reference>0</spring_reference>
          <spring_stiffness>0</spring_stiffness>
        </dynamics>
      </axis>
    </joint>
    <link name='Link_8'>
      <pose relative_to='VV1'>0 0 0 0 -0 0</pose>
      <inertial>
        <pose>5e-06 8e-06 0.004466 0 -0 0</pose>
        <mass>0.061748</mass>
        <inertia>
          <ixx>0.00011244</ixx>
          <ixy>-0.00026531</ixy>
          <ixz>-4.0465e-10</ixz>
          <iyy>0.0006823</iyy>
          <iyz>-6.3818e-10</iyz>
          <izz>0.00079419</izz>
        </inertia>
      </inertial>
      <collision name='Link_8_collision'>
        <pose>0 0 0 0 -0 0</pose>
        <geometry>
          <mesh>
            <scale>1 1 1</scale>
            <uri>model://airmedic/meshes/Link_8.dae</uri>
          </mesh>
        </geometry>
      </collision>
      <visual name='Link_8_visual'>
        <pose>0 0 0 0 -0 0</pose>
        <geometry>
          <mesh>
            <scale>1 1 1</scale>
            <uri>model://airmedic/meshes/Link_8.dae</uri>
          </mesh>
        </geometry>
        <material>
          <script>
            <name>Gazebo/Blue</name>
            <uri>__default__</uri>
          </script>
        </material>
      </visual>
    </link>
    <joint name='VV2' type='revolute'>
      <pose relative_to='base_link'>-0.642857 0.643017 0.221242 0 -0 0</pose>
      <parent>base_link</parent>
      <child>Link_9</child>
      <axis>
        <xyz>0 0 1</xyz>
        <limit>
          <lower>-1e+16</lower>
          <upper>1e+16</upper>
        </limit>
        <dynamics>
          <spring_reference>0</spring_reference>
          <spring_stiffness>0</spring_stiffness>
        </dynamics>
      </axis>
    </joint>
    <link name='Link_9'>
      <pose relative_to='VV2'>0 0 0 0 -0 0</pose>
      <inertial>
        <pose>2e-06 1e-05 0.004466 0 -0 0</pose>
        <mass>0.061748</mass>
        <inertia>
          <ixx>0.00037381</ixx>
          <ixy>-0.0003886</ixy>
          <ixz>-1.8103e-10</ixz>
          <iyy>0.00042092</iyy>
          <iyz>-7.6594e-10</iyz>
          <izz>0.00079418</izz>
        </inertia>
      </inertial>
      <collision name='Link_9_collision'>
        <pose>0 0 0 0 -0 0</pose>
        <geometry>
          <mesh>
            <scale>1 1 1</scale>
            <uri>model://airmedic/meshes/Link_9.dae</uri>
          </mesh>
        </geometry>
      </collision>
      <visual name='Link_9_visual'>
        <pose>0 0 0 0 -0 0</pose>
        <geometry>
          <mesh>
            <scale>1 1 1</scale>
            <uri>model://airmedic/meshes/Link_9.dae</uri>
          </mesh>
        </geometry>
        <material>
          <script>
            <name>Gazebo/Blue</name>
            <uri>__default__</uri>
          </script>
        </material>
      </visual>
    </link>
    <joint name='VV3' type='revolute'>
      <pose relative_to='base_link'>-0.642857 -0.642697 0.221242 0 -0 0</pose>
      <parent>base_link</parent>
      <child>Link_10</child>
      <axis>
        <xyz>0 0 1</xyz>
        <limit>
          <lower>-1e+16</lower>
          <upper>1e+16</upper>
        </limit>
        <dynamics>
          <spring_reference>0</spring_reference>
          <spring_stiffness>0</spring_stiffness>
        </dynamics>
      </axis>
    </joint>
    <link name='Link_10'>
      <pose relative_to='VV3'>0 0 0 0 -0 0</pose>
      <inertial>
        <pose>3e-06 1e-05 0.004466 0 -0 0</pose>
        <mass>0.061748</mass>
        <inertia>
          <ixx>0.00030209</ixx>
          <ixy>-0.00037748</ixy>
          <ixz>-1.9958e-10</ixz>
          <iyy>0.00049264</iyy>
          <iyz>-7.2573e-10</iyz>
          <izz>0.00079418</izz>
        </inertia>
      </inertial>
      <collision name='Link_10_collision'>
        <pose>0 0 0 0 -0 0</pose>
        <geometry>
          <mesh>
            <scale>1 1 1</scale>
            <uri>model://airmedic/meshes/Link_10.dae</uri>
          </mesh>
        </geometry>
      </collision>
      <visual name='Link_10_visual'>
        <pose>0 0 0 0 -0 0</pose>
        <geometry>
          <mesh>
            <scale>1 1 1</scale>
            <uri>model://airmedic/meshes/Link_10.dae</uri>
          </mesh>
        </geometry>
        <material>
          <script>
            <name>Gazebo/Blue</name>
            <uri>__default__</uri>
          </script>
        </material>
      </visual>
    </link>
    <joint name='VV4' type='revolute'>
      <pose relative_to='base_link'>0.642857 -0.642697 0.221242 0 -0 0</pose>
      <parent>base_link</parent>
      <child>Link_11</child>
      <axis>
        <xyz>0 0 1</xyz>
        <limit>
          <lower>-1e+16</lower>
          <upper>1e+16</upper>
        </limit>
        <dynamics>
          <spring_reference>0</spring_reference>
          <spring_stiffness>0</spring_stiffness>
        </dynamics>
      </axis>
    </joint>
    <link name='Link_11'>
      <pose relative_to='VV4'>0 0 0 0 -0 0</pose>
      <inertial>
        <pose>4e-06 9e-06 0.004466 0 -0 0</pose>
        <mass>0.061748</mass>
        <inertia>
          <ixx>0.00020984</ixx>
          <ixy>-0.00034118</ixy>
          <ixz>-2.9725e-10</ixz>
          <iyy>0.00058491</iyy>
          <iyz>-6.9454e-10</iyz>
          <izz>0.00079419</izz>
        </inertia>
      </inertial>
      <collision name='Link_11_collision'>
        <pose>0 0 0 0 -0 0</pose>
        <geometry>
          <mesh>
            <scale>1 1 1</scale>
            <uri>model://airmedic/meshes/Link_11.dae</uri>
          </mesh>
        </geometry>
      </collision>
      <visual name='Link_11_visual'>
        <pose>0 0 0 0 -0 0</pose>
        <geometry>
          <mesh>
            <scale>1 1 1</scale>
            <uri>model://airmedic/meshes/Link_11.dae</uri>
          </mesh>
        </geometry>
        <material>
          <script>
            <name>Gazebo/Blue</name>
            <uri>__default__</uri>
          </script>
        </material>
      </visual>
    </link>
    <joint name='VV5' type='revolute'>
      <pose relative_to='base_link'>-0.642857 0.643017 0.055422 0 -0 0</pose>
      <parent>base_link</parent>
      <child>Link_12</child>
      <axis>
        <xyz>0 0 1</xyz>
        <limit>
          <lower>-1e+16</lower>
          <upper>1e+16</upper>
        </limit>
        <dynamics>
          <spring_reference>0</spring_reference>
          <spring_stiffness>0</spring_stiffness>
        </dynamics>
      </axis>
    </joint>
    <link name='Link_12'>
      <pose relative_to='VV5'>0 0 0 0 -0 0</pose>
      <inertial>
        <pose>5e-06 9e-06 0.004466 0 -0 0</pose>
        <mass>0.061748</mass>
        <inertia>
          <ixx>0.00011244</ixx>
          <ixy>-0.0002653</ixy>
          <ixz>-3.3525e-10</ixz>
          <iyy>0.0006823</iyy>
          <iyz>-6.0502e-10</iyz>
          <izz>0.00079419</izz>
        </inertia>
      </inertial>
      <collision name='Link_12_collision'>
        <pose>0 0 0 0 -0 0</pose>
        <geometry>
          <mesh>
            <scale>1 1 1</scale>
            <uri>model://airmedic/meshes/Link_12.dae</uri>
          </mesh>
        </geometry>
      </collision>
      <visual name='Link_12_visual'>
        <pose>0 0 0 0 -0 0</pose>
        <geometry>
          <mesh>
            <scale>1 1 1</scale>
            <uri>model://airmedic/meshes/Link_12.dae</uri>
          </mesh>
        </geometry>
        <material>
          <script>
            <name>Gazebo/Blue</name>
            <uri>__default__</uri>
          </script>
        </material>
      </visual>
    </link>
    <joint name='VV6' type='revolute'>
      <pose relative_to='base_link'>0.642857 0.643017 0.055422 0 -0 0</pose>
      <parent>base_link</parent>
      <child>Link_13</child>
      <axis>
        <xyz>0 0 1</xyz>
        <limit>
          <lower>-1e+16</lower>
          <upper>1e+16</upper>
        </limit>
        <dynamics>
          <spring_reference>0</spring_reference>
          <spring_stiffness>0</spring_stiffness>
        </dynamics>
      </axis>
    </joint>
    <link name='Link_13'>
      <pose relative_to='VV6'>0 0 0 0 -0 0</pose>
      <inertial>
        <pose>3e-06 9e-06 0.004466 0 -0 0</pose>
        <mass>0.061748</mass>
        <inertia>
          <ixx>0.00020984</ixx>
          <ixy>-0.00034118</ixy>
          <ixz>-3.0935e-10</ixz>
          <iyy>0.00058491</iyy>
          <iyz>-7.0159e-10</iyz>
          <izz>0.00079419</izz>
        </inertia>
      </inertial>
      <collision name='Link_13_collision'>
        <pose>0 0 0 0 -0 0</pose>
        <geometry>
          <mesh>
            <scale>1 1 1</scale>
            <uri>model://airmedic/meshes/Link_13.dae</uri>
          </mesh>
        </geometry>
      </collision>
      <visual name='Link_13_visual'>
        <pose>0 0 0 0 -0 0</pose>
        <geometry>
          <mesh>
            <scale>1 1 1</scale>
            <uri>model://airmedic/meshes/Link_13.dae</uri>
          </mesh>
        </geometry>
        <material>
          <script>
            <name>Gazebo/Blue</name>
            <uri>__default__</uri>
          </script>
        </material>
      </visual>
    </link>
    <joint name='VV7' type='revolute'>
      <pose relative_to='base_link'>0.642857 -0.642697 0.055422 0 -0 0</pose>
      <parent>base_link</parent>
      <child>Link_14</child>
      <axis>
        <xyz>0 0 1</xyz>
        <limit>
          <lower>-1e+16</lower>
          <upper>1e+16</upper>
        </limit>
        <dynamics>
          <spring_reference>0</spring_reference>
          <spring_stiffness>0</spring_stiffness>
        </dynamics>
      </axis>
    </joint>
    <link name='Link_14'>
      <pose relative_to='VV7'>0 0 0 0 -0 0</pose>
      <inertial>
        <pose>3e-06 1e-05 0.004466 0 -0 0</pose>
        <mass>0.061748</mass>
        <inertia>
          <ixx>0.00030209</ixx>
          <ixy>-0.00037748</ixy>
          <ixz>-2.0406e-10</ixz>
          <iyy>0.00049265</iyy>
          <iyz>-7.2925e-10</iyz>
          <izz>0.00079418</izz>
        </inertia>
      </inertial>
      <collision name='Link_14_collision'>
        <pose>0 0 0 0 -0 0</pose>
        <geometry>
          <mesh>
            <scale>1 1 1</scale>
            <uri>model://airmedic/meshes/Link_14.dae</uri>
          </mesh>
        </geometry>
      </collision>
      <visual name='Link_14_visual'>
        <pose>0 0 0 0 -0 0</pose>
        <geometry>
          <mesh>
            <scale>1 1 1</scale>
            <uri>model://airmedic/meshes/Link_14.dae</uri>
          </mesh>
        </geometry>
        <material>
          <script>
            <name>Gazebo/Blue</name>
            <uri>__default__</uri>
          </script>
        </material>
      </visual>
    </link>
    <joint name='VV8' type='revolute'>
      <pose relative_to='base_link'>-0.642857 -0.642697 0.055422 0 -0 0</pose>
      <parent>base_link</parent>
      <child>Link_15</child>
      <axis>
        <xyz>0 0 1</xyz>
        <limit>
          <lower>-1e+16</lower>
          <upper>1e+16</upper>
        </limit>
        <dynamics>
          <spring_reference>0</spring_reference>
          <spring_stiffness>0</spring_stiffness>
        </dynamics>
      </axis>
    </joint>
    <link name='Link_15'>
      <pose relative_to='VV8'>0 0 0 0 -0 0</pose>
      <inertial>
        <pose>2e-06 1e-05 0.004466 0 -0 0</pose>
        <mass>0.061748</mass>
        <inertia>
          <ixx>0.00037381</ixx>
          <ixy>-0.0003886</ixy>
          <ixz>-1.7479e-10</ixz>
          <iyy>0.00042092</iyy>
          <iyz>-7.5933e-10</iyz>
          <izz>0.00079418</izz>
        </inertia>
      </inertial>
      <collision name='Link_15_collision'>
        <pose>0 0 0 0 -0 0</pose>
        <geometry>
          <mesh>
            <scale>1 1 1</scale>
            <uri>model://airmedic/meshes/Link_15.dae</uri>
          </mesh>
        </geometry>
      </collision>
      <visual name='Link_15_visual'>
        <pose>0 0 0 0 -0 0</pose>
        <geometry>
          <mesh>
            <scale>1 1 1</scale>
            <uri>model://airmedic/meshes/Link_15.dae</uri>
          </mesh>
        </geometry>
        <material>
          <script>
            <name>Gazebo/Blue</name>
            <uri>__default__</uri>
          </script>
        </material>
      </visual>
    </link>
    <joint name='VV9' type='revolute'>
      <pose relative_to='base_link'>0 0.57124 0.27623 0 -0 0</pose>
      <parent>base_link</parent>
      <child>Link_16</child>
      <axis>
        <xyz>0 1 0</xyz>
        <limit>
          <lower>-1e+16</lower>
          <upper>1e+16</upper>
        </limit>
        <dynamics>
          <spring_reference>0</spring_reference>
          <spring_stiffness>0</spring_stiffness>
        </dynamics>
      </axis>
    </joint>
    <link name='Link_16'>
      <pose relative_to='VV9'>0 0 0 0 -0 0</pose>
      <inertial>
        <pose>-6e-06 0.005585 -1e-05 0 -0 0</pose>
        <mass>0.1</mass>
        <inertia>
          <ixx>0.0002112</ixx>
          <ixy>-6.2472e-10</ixy>
          <ixz>-0.00049833</ixz>
          <iyy>0.0014917</iyy>
          <iyz>-1.1375e-09</iyz>
          <izz>0.0012816</izz>
        </inertia>
      </inertial>
      <collision name='Link_16_collision'>
        <pose>0 0 0 0 -0 0</pose>
        <geometry>
          <mesh>
            <scale>1 1 1</scale>
            <uri>model://airmedic/meshes/Link_16.dae</uri>
          </mesh>
        </geometry>
      </collision>
      <visual name='Link_16_visual'>
        <pose>0 0 0 0 -0 0</pose>
        <geometry>
          <mesh>
            <scale>1 1 1</scale>
            <uri>model://airmedic/meshes/Link_16.dae</uri>
          </mesh>
        </geometry>
        <material>
          <script>
            <name>Gazebo/Blue</name>
            <uri>__default__</uri>
          </script>
        </material>
      </visual>
    </link>
    <joint name='gps_joint' type='fixed'>
      <child>gps::link</child>
      <parent>base_link</parent>
    </joint>
    <joint name='airspeed_joint' type='fixed'>
      <child>airspeed::link</child>
      <parent>base_link</parent>
    </joint>
    <plugin name="left_wing_lift" filename="libLiftDragPlugin.so">
      <a0>0.05984281113</a0>
      <cla>4.752798721</cla>
      <cda>0.6417112299</cda>
      <cma>0.0</cma>
      <alpha_stall>0.3391428111</alpha_stall>
      <cla_stall>-3.85</cla_stall>
      <cda_stall>-0.9233984055</cda_stall>
      <cma_stall>0</cma_stall>
      <cp>-0.05 0.3 0.05</cp>
      <area>0.50</area>
      <air_density>1.2041</air_density>
      <forward>1 0 0</forward>
      <upward>0 0 1</upward>
      <link_name>base_link</link_name>
      <control_joint_name>
        EL_lev
      </control_joint_name>
      <control_joint_rad_to_cl>-1.0</control_joint_rad_to_cl>
      <robotNamespace></robotNamespace>
      <windSubTopic>world_wind</windSubTopic>
    </plugin>
    <plugin name="right_wing_lift" filename="libLiftDragPlugin.so">
      <a0>0.05984281113</a0>
      <cla>4.752798721</cla>
      <cda>0.6417112299</cda>
      <cma>0.0</cma>
      <alpha_stall>0.3391428111</alpha_stall>
      <cla_stall>-3.85</cla_stall>
      <cda_stall>-0.9233984055</cda_stall>
      <cma_stall>0</cma_stall>
      <cp>-0.05 -0.3 0.05</cp>
      <area>0.50</area>
      <air_density>1.2041</air_density>
      <forward>1 0 0</forward>
      <upward>0 0 1</upward>
      <link_name>base_link</link_name>
      <control_joint_name>
        EL_prav
      </control_joint_name>
      <control_joint_rad_to_cl>-1.0</control_joint_rad_to_cl>
      <robotNamespace></robotNamespace>
      <windSubTopic>world_wind</windSubTopic>
    </plugin>
    <plugin name="left_flap" filename="libLiftDragPlugin.so">
      <a0>0.05984281113</a0>
      <cla>4.752798721</cla>
      <cda>0.6417112299</cda>
      <cma>0.0</cma>
      <alpha_stall>0.3391428111</alpha_stall>
      <cla_stall>-3.85</cla_stall>
      <cda_stall>-0.9233984055</cda_stall>
      <cma_stall>0</cma_stall>
      <cp>-0.05 0.15 0.05</cp>
      <area>0.6</area>
      <air_density>1.2041</air_density>
      <forward>1 0 0</forward>
      <upward>0 0 1</upward>
      <link_name>base_link</link_name>
      <control_joint_name>
        ZAK_lev
      </control_joint_name>
      <control_joint_rad_to_cl>-0.5</control_joint_rad_to_cl>
      <robotNamespace></robotNamespace>
      <windSubTopic>world_wind</windSubTopic>
    </plugin>
    <plugin name="right_flap" filename="libLiftDragPlugin.so">
      <a0>0.05984281113</a0>
      <cla>4.752798721</cla>
      <cda>0.6417112299</cda>
      <cma>0.0</cma>
      <alpha_stall>0.3391428111</alpha_stall>
      <cla_stall>-3.85</cla_stall>
      <cda_stall>-0.9233984055</cda_stall>
      <cma_stall>0</cma_stall>
      <cp>-0.05 -0.15 0.05</cp>
      <area>0.6</area>
      <air_density>1.2041</air_density>
      <forward>1 0 0</forward>
      <upward>0 0 1</upward>
      <link_name>base_link</link_name>
      <control_joint_name>
        ZAK_prav
      </control_joint_name>
      <control_joint_rad_to_cl>-0.5</control_joint_rad_to_cl>
      <robotNamespace></robotNamespace>
      <windSubTopic>world_wind</windSubTopic>
    </plugin>
    <plugin name="right_elevator" filename="libLiftDragPlugin.so">
      <a0>-0.2</a0>
      <cla>4.752798721</cla>
      <cda>0.6417112299</cda>
      <cma>0.0</cma>
      <alpha_stall>0.3391428111</alpha_stall>
      <cla_stall>-3.85</cla_stall>
      <cda_stall>-0.9233984055</cda_stall>
      <cma_stall>0</cma_stall>
      <cp>-0.5 0 0</cp>
      <area>0.01</area>
      <air_density>1.2041</air_density>
      <forward>1 0 0</forward>
      <upward>0 0 1</upward>
      <link_name>base_link</link_name>
      <control_joint_name>
        RV_lev
      </control_joint_name>
      <control_joint_rad_to_cl>-4.0</control_joint_rad_to_cl>
      <robotNamespace></robotNamespace>
      <windSubTopic>world_wind</windSubTopic>
    </plugin>
    <plugin name="left_elevator" filename="libLiftDragPlugin.so">
      <a0>-0.2</a0>
      <cla>4.752798721</cla>
      <cda>0.6417112299</cda>
      <cma>0.0</cma>
      <alpha_stall>0.3391428111</alpha_stall>
      <cla_stall>-3.85</cla_stall>
      <cda_stall>-0.9233984055</cda_stall>
      <cma_stall>0</cma_stall>
      <cp>-0.5 0 0</cp>
      <area>0.01</area>
      <air_density>1.2041</air_density>
      <forward>1 0 0</forward>
      <upward>0 0 1</upward>
      <link_name>base_link</link_name>
      <control_joint_name>
        RV_prav
      </control_joint_name>
      <control_joint_rad_to_cl>-4.0</control_joint_rad_to_cl>
      <robotNamespace></robotNamespace>
      <windSubTopic>world_wind</windSubTopic>
    </plugin>
    <plugin name="rudder" filename="libLiftDragPlugin.so">
      <a0>0.0</a0>
      <cla>4.752798721</cla>
      <cda>0.6417112299</cda>
      <cma>0.0</cma>
      <alpha_stall>0.3391428111</alpha_stall>
      <cla_stall>-3.85</cla_stall>
      <cda_stall>-0.9233984055</cda_stall>
      <cma_stall>0</cma_stall>
      <cp>-0.5 0 0.05</cp>
      <area>0.02</area>
      <air_density>1.2041</air_density>
      <forward>1 0 0</forward>
      <upward>0 1 0</upward>
      <link_name>base_link</link_name>
      <control_joint_name>
         RN
      </control_joint_name>
      <control_joint_rad_to_cl>4.0</control_joint_rad_to_cl>
      <robotNamespace></robotNamespace>
      <windSubTopic>world_wind</windSubTopic>
    </plugin>
    <plugin name='VV1' filename='libgazebo_motor_model.so'>
      <robotNamespace></robotNamespace>
      <jointName>VV1</jointName>
      <linkName>Link_8</linkName>
      <turningDirection>ccw</turningDirection>
      <timeConstantUp>0.0125</timeConstantUp>
      <timeConstantDown>0.0125</timeConstantDown>
      <maxRotVelocity>4500</maxRotVelocity>
      <motorConstant>2.429e-04</motorConstant>
      <momentConstant>0.098</momentConstant>
      <commandSubTopic>/gazebo/command/motor_speed</commandSubTopic>
      <motorNumber>1</motorNumber>
      <rotorDragCoefficient>5.35e-03</rotorDragCoefficient>
      <rollingMomentCoefficient>2.99e-03</rollingMomentCoefficient>
      <motorSpeedPubTopic>/motor_speed/1</motorSpeedPubTopic>
      <rotorVelocitySlowdownSim>20</rotorVelocitySlowdownSim>
    </plugin>
    <plugin name='VV2' filename='libgazebo_motor_model.so'>
      <robotNamespace></robotNamespace>
      <jointName>VV2</jointName>
      <linkName>Link_9</linkName>
      <turningDirection>cw</turningDirection>
      <timeConstantUp>0.0125</timeConstantUp>
      <timeConstantDown>0.0125</timeConstantDown>
      <maxRotVelocity>4500</maxRotVelocity>
      <motorConstant>2.429e-04</motorConstant>
      <momentConstant>0.098</momentConstant>
      <commandSubTopic>/gazebo/command/motor_speed</commandSubTopic>
      <motorNumber>2</motorNumber>
      <rotorDragCoefficient>5.35e-03</rotorDragCoefficient>
      <rollingMomentCoefficient>2.99e-03</rollingMomentCoefficient>
      <motorSpeedPubTopic>/motor_speed/2</motorSpeedPubTopic>
      <rotorVelocitySlowdownSim>20</rotorVelocitySlowdownSim>
    </plugin>
    <plugin name='VV3' filename='libgazebo_motor_model.so'>
      <robotNamespace></robotNamespace>
      <jointName>VV3</jointName>
      <linkName>Link_10</linkName>
      <turningDirection>ccw</turningDirection>
      <timeConstantUp>0.0125</timeConstantUp>
      <timeConstantDown>0.0125</timeConstantDown>
      <maxRotVelocity>4500</maxRotVelocity>
      <motorConstant>2.429e-04</motorConstant>
      <momentConstant>0.098</momentConstant>
      <commandSubTopic>/gazebo/command/motor_speed</commandSubTopic>
      <motorNumber>3</motorNumber>
      <rotorDragCoefficient>5.35e-03</rotorDragCoefficient>
      <rollingMomentCoefficient>2.99e-03</rollingMomentCoefficient>
      <motorSpeedPubTopic>/motor_speed/3</motorSpeedPubTopic>
      <rotorVelocitySlowdownSim>20</rotorVelocitySlowdownSim>
    </plugin>
    <plugin name='VV4' filename='libgazebo_motor_model.so'>
      <robotNamespace></robotNamespace>
      <jointName>VV4</jointName>
      <linkName>Link_11</linkName>
      <turningDirection>cw</turningDirection>
      <timeConstantUp>0.0125</timeConstantUp>
      <timeConstantDown>0.0125</timeConstantDown>
      <maxRotVelocity>4500</maxRotVelocity>
      <motorConstant>2.429e-04</motorConstant>
      <momentConstant>0.098</momentConstant>
      <commandSubTopic>/gazebo/command/motor_speed</commandSubTopic>
      <motorNumber>4</motorNumber>
      <rotorDragCoefficient>5.35e-03</rotorDragCoefficient>
      <rollingMomentCoefficient>2.99e-03</rollingMomentCoefficient>
      <motorSpeedPubTopic>/motor_speed/4</motorSpeedPubTopic>
      <rotorVelocitySlowdownSim>20</rotorVelocitySlowdownSim>
    </plugin>
    <plugin name='VV5' filename='libgazebo_motor_model.so'>
      <robotNamespace></robotNamespace>
      <jointName>VV5</jointName>
      <linkName>Link_12</linkName>
      <turningDirection>ccw</turningDirection>
      <timeConstantUp>0.0125</timeConstantUp>
      <timeConstantDown>0.0125</timeConstantDown>
      <maxRotVelocity>4500</maxRotVelocity>
      <motorConstant>2.429e-04</motorConstant>
      <momentConstant>0.098</momentConstant>
      <commandSubTopic>/gazebo/command/motor_speed</commandSubTopic>
      <motorNumber>5</motorNumber>
      <rotorDragCoefficient>5.35e-03</rotorDragCoefficient>
      <rollingMomentCoefficient>2.99e-03</rollingMomentCoefficient>
      <motorSpeedPubTopic>/motor_speed/5</motorSpeedPubTopic>
      <rotorVelocitySlowdownSim>20</rotorVelocitySlowdownSim>
    </plugin>
    <plugin name='VV6' filename='libgazebo_motor_model.so'>
      <robotNamespace></robotNamespace>
      <jointName>VV6</jointName>
      <linkName>Link_13</linkName>
      <turningDirection>cw</turningDirection>
      <timeConstantUp>0.0125</timeConstantUp>
      <timeConstantDown>0.0125</timeConstantDown>
      <maxRotVelocity>4500</maxRotVelocity>
      <motorConstant>2.429e-04</motorConstant>
      <momentConstant>0.098</momentConstant>
      <commandSubTopic>/gazebo/command/motor_speed</commandSubTopic>
      <motorNumber>6</motorNumber>
      <rotorDragCoefficient>5.35e-03</rotorDragCoefficient>
      <rollingMomentCoefficient>2.99e-03</rollingMomentCoefficient>
      <motorSpeedPubTopic>/motor_speed/6</motorSpeedPubTopic>
      <rotorVelocitySlowdownSim>20</rotorVelocitySlowdownSim>
    </plugin>
    <plugin name='VV7' filename='libgazebo_motor_model.so'>
      <robotNamespace></robotNamespace>
      <jointName>VV7</jointName>
      <linkName>Link_14</linkName>
      <turningDirection>ccw</turningDirection>
      <timeConstantUp>0.0125</timeConstantUp>
      <timeConstantDown>0.0125</timeConstantDown>
      <maxRotVelocity>4500</maxRotVelocity>
      <motorConstant>2.429e-04</motorConstant>
      <momentConstant>0.098</momentConstant>
      <commandSubTopic>/gazebo/command/motor_speed</commandSubTopic>
      <motorNumber>7</motorNumber>
      <rotorDragCoefficient>5.35e-03</rotorDragCoefficient>
      <rollingMomentCoefficient>2.99e-03</rollingMomentCoefficient>
      <motorSpeedPubTopic>/motor_speed/7</motorSpeedPubTopic>
      <rotorVelocitySlowdownSim>20</rotorVelocitySlowdownSim>
    </plugin>
    <plugin name='VV8' filename='libgazebo_motor_model.so'>
      <robotNamespace></robotNamespace>
      <jointName>VV8</jointName>
      <linkName>Link_15</linkName>
      <turningDirection>cw</turningDirection>
      <timeConstantUp>0.0125</timeConstantUp>
      <timeConstantDown>0.0125</timeConstantDown>
      <maxRotVelocity>4500</maxRotVelocity>
      <motorConstant>2.429e-04</motorConstant>
      <momentConstant>0.098</momentConstant>
      <commandSubTopic>/gazebo/command/motor_speed</commandSubTopic>
      <motorNumber>8</motorNumber>
      <rotorDragCoefficient>5.35e-03</rotorDragCoefficient>
      <rollingMomentCoefficient>2.99e-03</rollingMomentCoefficient>
      <motorSpeedPubTopic>/motor_speed/8</motorSpeedPubTopic>
      <rotorVelocitySlowdownSim>20</rotorVelocitySlowdownSim>
    </plugin>
    <plugin name='VV9' filename='libgazebo_motor_model.so'>
      <robotNamespace></robotNamespace>
      <jointName>VV9</jointName>
      <linkName>Link_16</linkName>
      <turningDirection>cw</turningDirection>
      <timeConstantUp>0.0125</timeConstantUp>
      <timeConstantDown>0.025</timeConstantDown>
      <maxRotVelocity>3500</maxRotVelocity>
      <motorConstant>8.54858e-06</motorConstant>
      <momentConstant>0.01</momentConstant>
      <commandSubTopic>/gazebo/command/motor_speed</commandSubTopic>
      <motorNumber>9</motorNumber>
      <rotorDragCoefficient>0.000106428</rotorDragCoefficient>
      <rollingMomentCoefficient>1e-06</rollingMomentCoefficient>
      <motorSpeedPubTopic>/motor_speed/9</motorSpeedPubTopic>
      <rotorVelocitySlowdownSim>20</rotorVelocitySlowdownSim>
    </plugin>
    <plugin name='gazebo_imu_plugin' filename='libgazebo_imu_plugin.so'>
      <robotNamespace></robotNamespace>
      <linkName>airmedic/imu_link</linkName>
      <imuTopic>/imu</imuTopic>
      <gyroscopeNoiseDensity>0.0003394</gyroscopeNoiseDensity>
      <gyroscopeRandomWalk>3.8785e-05</gyroscopeRandomWalk>
      <gyroscopeBiasCorrelationTime>1000.0</gyroscopeBiasCorrelationTime>
      <gyroscopeTurnOnBiasSigma>0.0087</gyroscopeTurnOnBiasSigma>
      <accelerometerNoiseDensity>0.004</accelerometerNoiseDensity>
      <accelerometerRandomWalk>0.001</accelerometerRandomWalk>
      <accelerometerBiasCorrelationTime>300.0</accelerometerBiasCorrelationTime>
      <accelerometerTurnOnBiasSigma>0.196</accelerometerTurnOnBiasSigma>
    </plugin>
    <plugin name='groundtruth_plugin' filename='libgazebo_groundtruth_plugin.so'>
      <robotNamespace/>
    </plugin>
    <plugin name='magnetometer_plugin' filename='libgazebo_magnetometer_plugin.so'>
      <robotNamespace/>
      <pubRate>100</pubRate>
      <noiseDensity>0.0004</noiseDensity>
      <randomWalk>6.4e-06</randomWalk>
      <biasCorrelationTime>600</biasCorrelationTime>
      <magTopic>/mag</magTopic>
    </plugin>
    <plugin name='barometer_plugin' filename='libgazebo_barometer_plugin.so'>
      <robotNamespace/>
      <pubRate>50</pubRate>
      <baroTopic>/baro</baroTopic>
    </plugin>
    <plugin name='mavlink_interface' filename='libgazebo_mavlink_interface.so'>
      <robotNamespace></robotNamespace>
      <imuSubTopic>/imu</imuSubTopic>
      <magSubTopic>/mag</magSubTopic>
      <baroSubTopic>/baro</baroSubTopic>
      <mavlink_addr>INADDR_ANY</mavlink_addr>
      <mavlink_tcp_port>4560</mavlink_tcp_port>
      <mavlink_udp_port>14560</mavlink_udp_port>
      <serialEnabled>0</serialEnabled>
      <serialDevice>/dev/ttyACM0</serialDevice>
      <baudRate>921600</baudRate>
      <qgc_addr>INADDR_ANY</qgc_addr>
      <qgc_udp_port>14550</qgc_udp_port>
      <sdk_addr>INADDR_ANY</sdk_addr>
      <sdk_udp_port>14540</sdk_udp_port>
      <hil_mode>0</hil_mode>
      <hil_state_level>false</hil_state_level>
      <enable_lockstep>true</enable_lockstep>
      <use_tcp>true</use_tcp>
      <motorSpeedCommandPubTopic>/gazebo/command/motor_speed</motorSpeedCommandPubTopic>
      <control_channels>
        <channel name="VV1">
          <input_index>0</input_index>
          <input_offset>0</input_offset>
          <input_scaling>4500</input_scaling>
          <zero_position_disarmed>0</zero_position_disarmed>
          <zero_position_armed>0</zero_position_armed>
          <joint_control_type>velocity</joint_control_type>
          <joint_name>VV1</joint_name>
        </channel>
        <channel name="VV2">
          <input_index>1</input_index>
          <input_offset>0</input_offset>
          <input_scaling>4500</input_scaling>
          <zero_position_disarmed>0</zero_position_disarmed>
          <zero_position_armed>0</zero_position_armed>
          <joint_control_type>velocity</joint_control_type>
          <joint_name>VV2</joint_name>
        </channel>
        <channel name="VV3">
          <input_index>2</input_index>
          <input_offset>0</input_offset>
          <input_scaling>4500</input_scaling>
          <zero_position_disarmed>0</zero_position_disarmed>
          <zero_position_armed>0</zero_position_armed>
          <joint_control_type>velocity</joint_control_type>
          <joint_name>VV3</joint_name>
        </channel>
        <channel name="VV4">
          <input_index>3</input_index>
          <input_offset>0</input_offset>
          <input_scaling>4500</input_scaling>
          <zero_position_disarmed>0</zero_position_disarmed>
          <zero_position_armed>0</zero_position_armed>
          <joint_control_type>velocity</joint_control_type>
          <joint_name>VV4</joint_name>
        </channel>
        <channel name="VV5">
          <input_index>4</input_index>
          <input_offset>0</input_offset>
          <input_scaling>4500</input_scaling>
          <zero_position_disarmed>0</zero_position_disarmed>
          <zero_position_armed>0</zero_position_armed>
          <joint_control_type>velocity</joint_control_type>
          <joint_name>VV5</joint_name>
        </channel>
        <channel name="VV6">
          <input_index>5</input_index>
          <input_offset>0</input_offset>
          <input_scaling>4500</input_scaling>
          <zero_position_disarmed>0</zero_position_disarmed>
          <zero_position_armed>0</zero_position_armed>
          <joint_control_type>velocity</joint_control_type>
          <joint_name>VV6</joint_name>
        </channel>
        <channel name="VV7">
          <input_index>6</input_index>
          <input_offset>0</input_offset>
          <input_scaling>4500</input_scaling>
          <zero_position_disarmed>0</zero_position_disarmed>
          <zero_position_armed>0</zero_position_armed>
          <joint_control_type>velocity</joint_control_type>
          <joint_name>VV7</joint_name>
        </channel>
        <channel name="VV8">
          <input_index>7</input_index>
          <input_offset>0</input_offset>
          <input_scaling>4500</input_scaling>
          <zero_position_disarmed>0</zero_position_disarmed>
          <zero_position_armed>0</zero_position_armed>
          <joint_control_type>velocity</joint_control_type>
          <joint_name>VV8</joint_name>
        </channel>
        <channel name="VV9">
          <input_index>8</input_index>
          <input_offset>0</input_offset>
          <input_scaling>3500</input_scaling>
          <zero_position_disarmed>0</zero_position_disarmed>
          <zero_position_armed>0</zero_position_armed>
          <joint_control_type>velocity</joint_control_type>
          <joint_name>VV9</joint_name>
        </channel>
        <channel name="EL_lev">
          <input_index>9</input_index>
          <input_offset>0</input_offset>
          <input_scaling>1</input_scaling>
          <zero_position_disarmed>0</zero_position_disarmed>
          <zero_position_armed>0</zero_position_armed>
          <joint_control_type>position_kinematic</joint_control_type>
          <joint_name>EL_lev</joint_name>
        </channel>
        <channel name="EL_prav">
          <input_index>10</input_index>
          <input_offset>0</input_offset>
          <input_scaling>1</input_scaling>
          <zero_position_disarmed>0</zero_position_disarmed>
          <zero_position_armed>0</zero_position_armed>
          <joint_control_type>position_kinematic</joint_control_type>
          <joint_name>EL_prav</joint_name>
        </channel>
        <channel name="RN">
          <input_index>11</input_index>
          <input_offset>0</input_offset>
          <input_scaling>1</input_scaling>
          <zero_position_disarmed>0</zero_position_disarmed>
          <zero_position_armed>0</zero_position_armed>
          <joint_control_type>position_kinematic</joint_control_type>
          <joint_name>RN</joint_name>
        </channel>
        <channel name="RV_lev">
          <input_index>12</input_index>
          <input_offset>0</input_offset>
          <input_scaling>1</input_scaling>
          <zero_position_disarmed>0</zero_position_disarmed>
          <zero_position_armed>0</zero_position_armed>
          <joint_control_type>position_kinematic</joint_control_type>
          <joint_name>RV_lev</joint_name>
        </channel>
        <channel name="RV_prav">
          <input_index>13</input_index>
          <input_offset>0</input_offset>
          <input_scaling>1</input_scaling>
          <zero_position_disarmed>0</zero_position_disarmed>
          <zero_position_armed>0</zero_position_armed>
          <joint_control_type>position_kinematic</joint_control_type>
          <joint_name>RV_prav</joint_name>
        </channel>
        <channel name="ZAK_lev">
          <input_index>14</input_index>
          <input_offset>0</input_offset>
          <input_scaling>1</input_scaling>
          <zero_position_disarmed>0</zero_position_disarmed>
          <zero_position_armed>0</zero_position_armed>
          <joint_control_type>position_kinematic</joint_control_type>
          <joint_name>ZAK_lev</joint_name>
        </channel>
        <channel name="ZAK_prav">
          <input_index>15</input_index>
          <input_offset>0</input_offset>
          <input_scaling>1</input_scaling>
          <zero_position_disarmed>0</zero_position_disarmed>
          <zero_position_armed>0</zero_position_armed>
          <joint_control_type>position_kinematic</joint_control_type>
          <joint_name>ZAK_prav</joint_name>
        </channel>
      </control_channels>
    </plugin>
  </model>
</sdf>
